<!-- Note: Component inertias are known to be incorrect in this version -->
<mujoco model='dubPend'>
  <compiler inertiafromgeom='false' angle='degree' eulerseq='zyx' meshdir='cassie-stl-meshes'/>
  <size nuser_actuator='1' nuser_sensor='1'/>
  <option timestep='0.0005' iterations='50' solver='PGS' gravity='0 0 0'/>
  <!-- Timestep is set to 0.0005 because our controller runs at 2 kHz (-9.806)-->
  <!-- Larger values still have stable dynamics -->

  <visual>
    <quality shadowsize='4096'/>
    <map znear='0.05'/>
  </visual>

  <default>
    <joint limited='true'/>
    <geom contype='0' conaffinity='0' condim='1'  solref=".005 1" solimp=".8 .8 .01" material='cassie'/>
    <motor ctrllimited='true'/>
  </default>

  <asset>
    <texture type='skybox' builtin='gradient' width='128' height='128' rgb1='0.725490196078431   0.403921568627451   1.000000000000000' rgb2='1.000000000000000   0.984313725490196   0.588235294117647'/>
    <texture name='plane' type='2d' builtin='checker'  rgb1='1.000000000000000   0.443137254901961   0.807843137254902' rgb2='0.019607843137255   1.000000000000000   0.631372549019608' width='128' height='128'/>
    <material name='plane' reflectance='0.0' texture='plane' texrepeat='4 4' texuniform='true'/>
    <material name='cassie' rgba='0.003921568627451   0.803921568627451   0.996078431372549 1'/>
  </asset>

  <worldbody>
    <geom name='floor' pos='0 0 -0.1' size='5 5 .125' type='plane' material='plane' condim='3' conaffinity='7'/>
    <light mode='trackcom' pos='0 0 5' dir='0 0 -1'/>
    <light directional='true' pos='0 0 3' dir='0 0 -1' diffuse='0.2 0.2 0.2' specular='0 0 0'/>
    <camera name='trackcom' pos='0 -3 2' zaxis='0 -1 0.5' mode='trackcom'/>

    <body name = 'body_a' pos='0 0 0'>
      <inertial pos ='0.5 0 0' mass = '1' diaginertia='0.1 0.1 0.1'/>
      <joint name='joint_a' type='hinge' range='-175 175'/>
      <geom type='capsule' fromto='0 0 0 1 0 0' size='0.05'/>
      <body name = 'body_b' pos='1 0 0'>
        <inertial pos ='0.5 0 0' mass = '1' diaginertia='0.1 0.1 0.1'/>
        <joint name='joint_b' type='hinge' range='-175 175'/>
        <geom type='capsule' fromto='0 0 0 1 0 0' size='0.05'/>        
        <site name='end_effector' size='0.1' pos='1 0 0'/>
      </body>
    </body>
  </worldbody>

  <actuator>
    <!-- User parameter is the maximum no-load motor RPM -->
    <motor name='motor_a' joint='joint_a' ctrllimited='false' user='1300'/>
    <motor name='motor_b' joint='joint_b' ctrllimited='false' user='1300'/>
  </actuator>

</mujoco>
